Workbook

Sheet Quotation
A1: SUDARSHAN PIPES
A2: [Registered office address] | GSTIN: [to fill] | Phone: [to fill] | Email: [to fill]
A3: QUOTATION
A5: Quotation No. | C5: SP/2026-27/____ | H5: Date | J5: 15-Oct-2026
A6: To | C6: Sri Veerabhadragouda Patil (Prime Contractor), Joint Venture with Infracon Structures, Prop. Pramodh Anand | H6: Valid for (days) | J6: 30
A7: Project | C7: MGNVY-2.0, Package-02: Comprehensive development of arterial & sub-arterial roads with underground conduits for utilities under Urban Connectivity, Belagavi City Corporation limits (DMA/2025-26/RD/WORK_INDENT38534) | H7: Supply type | J7: Intra-state (Karnataka)
A8: Reference | C8: Directorate of Municipal Administration, Itemwise Schedule-B. Agreement No. 1740586/DMA/TECH/MGNV/12/2025-26/AGR-__ (verify from BOQ). Quantities as per BOQ. | H8: GST % | J8: 0.18
A10: S.No | B10: BOQ Item No. | C10: BOQ Item Code | D10: Description (as per BOQ) | E10: Size (mm) | F10: Unit | G10: Qty | H10: Rate (Rs/unit) | I10: Amount (Rs) | J10: HSN | K10: Remarks / check before sending
A11: A. Plastic pipes (HDPE / DWC / PVC) in the BOQ
A12: 1 | B12: 72 | C12: 9.1.4 | D12: HDPE pipe, grade PE80, PN 6.0, conforming to IS 4984:2016. BOQ note: up to 110 mm dia supplied in coil. | E12: 110 | F12: m | G12: 45398.8 | I12: =IF(H12="","",ROUND(G12*H12,2)) | J12: 3917 | K12: BOQ asks PE80 PN6.0. Confirm grade offered and coil length.
A13: 2 | B13: 73 | C13: 9.1.9 | D13: HDPE pipe, grade PE80, PN 6.0, conforming to IS 4984:2016. | E13: 200 | F13: m | G13: 22699.4 | I13: =IF(H13="","",ROUND(G13*H13,2)) | J13: 3917 | K13: Confirm PE80 PN6.0 and supply length (straight lengths/coil).
A14: 3 | B14: 74 | C14: 9.16.10 | D14: Class SN8 double wall corrugated HDPE pipe (outer wall corrugated, inner wall smooth) as per IS 16098 Part 2, with coupler and two O-rings per joint. | E14: 600 | F14: m | G14: 1700 | I14: =IF(H14="","",ROUND(G14*H14,2)) | J14: 3917 | K14: Confirm SN8 600 mm availability; BOQ says approved make/spec.
A15: 4 | B15: 75 | C15: 9.16.6 | D15: Class SN8 double wall corrugated HDPE pipe as per IS 16098 Part 2, with coupler and two O-rings per joint. | E15: 250 | F15: m | G15: 3462 | I15: =IF(H15="","",ROUND(G15*H15,2)) | J15: 3917 | K15: Confirm SN8 250 mm availability.
A16: 5 | B16: 76 | C16: 9.16.7 | D16: Class SN8 double wall corrugated HDPE pipe as per IS 16098 Part 2, with coupler and two O-rings per joint. | E16: 300 | F16: m | G16: 2368 | I16: =IF(H16="","",ROUND(G16*H16,2)) | J16: 3917 | K16: Confirm SN8 300 mm availability.
A17: 6 | B17: 11 | C17: 12.2 | D17: PVC pipe 110 mm outer dia, 2 kg per sqm, for weep holes through the full width of the structure (pipe supply only). | E17: 110 | F17: m | G17: 459.8 | I17: =IF(H17="","",ROUND(G17*H17,2)) | J17: 3917 | K17: BOQ item is composite (masonry + pipe). Quote pipe supply only; item code printed as 12.2 on two lines, verify.
A18: B. Other pipe items in the BOQ (not in our standard range: review)
A19: 7 | B19: 12 | C19: 12.2 | D19: Glazed stoneware pipe, IS 651:1992 / IS 4127 (house service connection). | E19: 100 | F19: m | G19: 135 | I19: =IF(H19="","",ROUND(G19*H19,2)) | K19: Not HDPE/PVC. Quote or delete after review.
A20: 8 | B20: 13 | C20: 16.1.1 | D20: Glazed stoneware pipe, IS 651:1992 / IS 4127 (house service connection). | E20: 100 | F20: m | G20: 1156 | I20: =IF(H20="","",ROUND(G20*H20,2)) | K20: Not HDPE/PVC. Quote or delete after review.
A21: 9 | B21: 14 | C21: 16.1.2 | D21: Glazed stoneware pipe, IS 651:1992 / IS 4127. | E21: 150 | F21: m | G21: 2288 | I21: =IF(H21="","",ROUND(G21*H21,2)) | K21: Not HDPE/PVC. Quote or delete after review.
A22: 10 | B22: 15 | C22: 16.1.4 | D22: Glazed stoneware pipe, IS 651:1992 / IS 4127. | E22: 230 | F22: m | G22: 573.75 | I22: =IF(H22="","",ROUND(G22*H22,2)) | K22: Not HDPE/PVC. Quote or delete after review.
A24: Sub-total | I24: =SUM(I11:I22) -> 0
A25: Discount % (optional) | I25: 0
A26: Discount amount | I26: =ROUND(I24*I25,2) -> 0
A27: Freight / loading (optional) | I27: 0
A28: Taxable value | I28: =I24-I26+I27 -> 0
A29: CGST | I29: =IF($J$7="Intra-state (Karnataka)",ROUND(I28*$J$8/2,2),0) -> 0
A30: SGST | I30: =IF($J$7="Intra-state (Karnataka)",ROUND(I28*$J$8/2,2),0) -> 0
A31: IGST | I31: =IF($J$7="Inter-state",ROUND(I28*$J$8,2),0) -> 0
A32: GRAND TOTAL (Rs) | I32: =I28+I29+I30+I31 -> 0
A34: Amount in words: | C34: [type the grand total in words once rates are filled]
A36: Terms & conditions
A37: • Scope: SUPPLY ONLY of pipes. Excavation, laying, jointing, testing, special fittings (saddle tee, stub ends, flanged sets, bends, reducers) and water for testing are excluded unless stated. Fittings quoted separately on request.
A38: • Prices: ex-works / delivered to site: [select and fill]. Freight and unloading as per the line above.
A39: • GST: as applicable and shown above. Rates exclude any other taxes or levies.
A40: • Payment terms: [to fill].
A41: • Delivery: [to fill] weeks from receipt of confirmed purchase order / site schedule.
A42: • Validity: as stated in the header from the date of quotation.
A43: • Material conforms to the IS standards quoted in the description. Test certificates supplied with each lot.
A44: • Bank details: [Bank name, account name, account number, IFSC] (fill before sending).
A46: For SUDARSHAN PIPES
...

Sheet Internal - do not send
A1: INTERNAL REFERENCE: contract rates from the BOQ (the contractor's rates for supply + laying + jointing + testing). NEVER use as our rate. Do not send this sheet.
A3: BOQ S.No | B3: Item Code | C3: Unit | D3: Qty (BOQ) | E3: Contract rate (ref) | F3: Contract amount (BOQ) | G3: Qty x rate (check) | H3: Difference | I3: Our rate (from Quotation) | J3: Our rate vs contract rate
A4: 72 | B4: 9.1.4 | C4: m | D4: =Quotation!G12 -> 45398.8 | E4: 470 | F4: 21337436 | G4: =ROUND(D4*E4,2) -> 21337436 | H4: =ROUND(F4-G4,2) -> 0 | I4: =IF(Quotation!H12="","",Quotation!H12) | J4: =IF(I4="","",IF(I4>E4,"ABOVE contract rate: check","OK"))
A5: 73 | B5: 9.1.9 | C5: m | D5: =Quotation!G13 -> 22699.4 | E5: 1500 | F5: 34049100 | G5: =ROUND(D5*E5,2) -> 34049100 | H5: =ROUND(F5-G5,2) -> 0 | I5: =IF(Quotation!H13="","",Quotation!H13) | J5: =IF(I5="","",IF(I5>E5,"ABOVE contract rate: check","OK"))
A6: 74 | B6: 9.16.10 | C6: m | D6: =Quotation!G14 -> 1700 | E6: 6406 | F6: 10890200 | G6: =ROUND(D6*E6,2) -> 10890200 | H6: =ROUND(F6-G6,2) -> 0 | I6: =IF(Quotation!H14="","",Quotation!H14) | J6: =IF(I6="","",IF(I6>E6,"ABOVE contract rate: check","OK"))
A7: 75 | B7: 9.16.6 | C7: m | D7: =Quotation!G15 -> 3462 | E7: 1244 | F7: 4306728 | G7: =ROUND(D7*E7,2) -> 4306728 | H7: =ROUND(F7-G7,2) -> 0 | I7: =IF(Quotation!H15="","",Quotation!H15) | J7: =IF(I7="","",IF(I7>E7,"ABOVE contract rate: check","OK"))
A8: 76 | B8: 9.16.7 | C8: m | D8: =Quotation!G16 -> 2368 | E8: 1655 | F8: 3919040 | G8: =ROUND(D8*E8,2) -> 3919040 | H8: =ROUND(F8-G8,2) -> 0 | I8: =IF(Quotation!H16="","",Quotation!H16) | J8: =IF(I8="","",IF(I8>E8,"ABOVE contract rate: check","OK"))
A9: 11 | B9: 12.2 | C9: m | D9: =Quotation!G17 -> 459.8 | E9: 263 | F9: 120927.4 | G9: =ROUND(D9*E9,2) -> 120927.4 | H9: =ROUND(F9-G9,2) -> 0 | I9: =IF(Quotation!H17="","",Quotation!H17) | J9: =IF(I9="","",IF(I9>E9,"ABOVE contract rate: check","OK"))
A10: 12 | B10: 12.2 | C10: m | D10: =Quotation!G19 -> 135 | E10: 407 | F10: 54945 | G10: =ROUND(D10*E10,2) -> 54945 | H10: =ROUND(F10-G10,2) -> 0 | I10: =IF(Quotation!H19="","",Quotation!H19) | J10: =IF(I10="","",IF(I10>E10,"ABOVE contract rate: check","OK"))
A11: 13 | B11: 16.1.1 | C11: m | D11: =Quotation!G20 -> 1156 | E11: 407 | F11: 470492 | G11: =ROUND(D11*E11,2) -> 470492 | H11: =ROUND(F11-G11,2) -> 0 | I11: =IF(Quotation!H20="","",Quotation!H20) | J11: =IF(I11="","",IF(I11>E11,"ABOVE contract rate: check","OK"))
A12: 14 | B12: 16.1.2 | C12: m | D12: =Quotation!G21 -> 2288 | E12: 640 | F12: 1464320 | G12: =ROUND(D12*E12,2) -> 1464320 | H12: =ROUND(F12-G12,2) -> 0 | I12: =IF(Quotation!H21="","",Quotation!H21) | J12: =IF(I12="","",IF(I12>E12,"ABOVE contract rate: check","OK"))
A13: 15 | B13: 16.1.4 | C13: m | D13: =Quotation!G22 -> 573.75 | E13: 971 | F13: 557111.25 | G13: =ROUND(D13*E13,2) -> 557111.25 | H13: =ROUND(F13-G13,2) -> 0 | I13: =IF(Quotation!H22="","",Quotation!H22) | J13: =IF(I13="","",IF(I13>E13,"ABOVE contract rate: check","OK"))
A15: Source: BOQ pages 2, 12, 13 (rate and amount as printed). Difference column should be 0 (tolerance Rs 1); blue = typed from the scan.
A16: Contract rate includes laying, jointing, testing and the contractor's margin, so it is only a rough ceiling for a supply-only price.
